<?xml version="1.0" ?>
<!-- =================================================================================== -->
<!-- |    This document was autogenerated by xacro from src/chapter7_tutorials/rosbook_arm_description/robots/rosbook_arm_base.urdf.xacro | -->
<!-- |    EDITING THIS FILE BY HAND IS NOT RECOMMENDED                                 | -->
<!-- =================================================================================== -->
<robot name="rosbook_arm">
  <gazebo>
    <plugin filename="libgazebo_ros_control.so" name="gazebo_ros_control">
      <ns/>
      <robotSimType>rosbook_arm_hardware_gazebo/ROSBookArmHardwareGazebo</robotSimType>
      <controlPeriod>0.001</controlPeriod>
    </plugin>
  </gazebo>
  <material name="green">
    <color rgba="0.0 1.0 0.0 1.0"/>
  </material>
  <material name="white">
    <color rgba="1.0 1.0 1.0 1.0"/>
  </material>
  <link name="base_link">
    <visual>
      <geometry>
        <cylinder length="0.01" radius="0.5"/>
      </geometry>
      <origin xyz="0.0 0.0 0.0"/>
      <material name="white"/>
    </visual>
    <collision>
      <geometry>
        <cylinder length="0.01" radius="0.5"/>
      </geometry>
      <origin xyz="0.0 0.0 0.0"/>
    </collision>
    <inertial>
      <origin xyz="0.0 0.0 0.0"/>
      <mass value="1"/>
      <inertia ixx="0.06250833333333333" ixy="0.0" ixz="0.0" iyy="0.06250833333333333" iyz="0.0" izz="0.125"/>
    </inertial>
  </link>
  <!-- Simulation (gazebo) -->
  <base_gazebo/>
  <link name="shoulder_link">
    <visual>
      <geometry>
        <cylinder length="0.5" radius="0.25"/>
      </geometry>
      <origin xyz="0.0 0.0 0.25"/>
      <material name="white"/>
    </visual>
    <collision>
      <geometry>
        <cylinder length="0.5" radius="0.25"/>
      </geometry>
      <origin xyz="0.0 0.0 0.25"/>
    </collision>
    <inertial>
      <origin xyz="0.0 0.0 0.25"/>
      <mass value="0.01"/>
      <inertia ixx="0.0003645833333333333" ixy="0.0" ixz="0.0" iyy="0.0003645833333333333" iyz="0.0" izz="0.0003125"/>
    </inertial>
  </link>
  <link name="upper_arm_link">
    <visual>
      <geometry>
        <cylinder length="1" radius="0.25"/>
      </geometry>
      <origin xyz="0.0 0.0 0.5"/>
      <material name="white"/>
    </visual>
    <collision>
      <geometry>
        <cylinder length="1" radius="0.25"/>
      </geometry>
      <origin xyz="0.0 0.0 0.5"/>
    </collision>
    <inertial>
      <origin xyz="0.0 0.0 0.5"/>
      <mass value="0.01"/>
      <inertia ixx="0.0009895833333333332" ixy="0.0" ixz="0.0" iyy="0.0009895833333333332" iyz="0.0" izz="0.0003125"/>
    </inertial>
  </link>
  <link name="forearm_link">
    <visual>
      <geometry>
        <cylinder length="1" radius="0.25"/>
      </geometry>
      <origin xyz="0.0 0.0 0.5"/>
      <material name="white"/>
    </visual>
    <collision>
      <geometry>
        <cylinder length="1" radius="0.25"/>
      </geometry>
      <origin xyz="0.0 0.0 0.5"/>
    </collision>
    <inertial>
      <origin xyz="0.0 0.0 0.5"/>
      <mass value="0.01"/>
      <inertia ixx="0.0009895833333333332" ixy="0.0" ixz="0.0" iyy="0.0009895833333333332" iyz="0.0" izz="0.0003125"/>
    </inertial>
  </link>
  <link name="rotor_0_link">
    <visual>
      <geometry>
        <cylinder length="0.5" radius="0.25"/>
      </geometry>
      <origin rpy="1.57079633 0.0 0.0" xyz="0.0 0.0 0.5"/>
      <material name="green"/>
    </visual>
    <collision>
      <geometry>
        <cylinder length="0.5" radius="0.25"/>
      </geometry>
      <origin rpy="1.57079633 0.0 0.0" xyz="0.0 0.0 0.5"/>
    </collision>
    <inertial>
      <origin rpy="1.57079633 0.0 0.0" xyz="0.0 0.0 0.5"/>
      <mass value="0.01"/>
      <inertia ixx="0.0003645833333333333" ixy="0.0" ixz="0.0" iyy="0.0003645833333333333" iyz="0.0" izz="0.0003125"/>
    </inertial>
  </link>
  <link name="rotor_1_link">
    <visual>
      <geometry>
        <cylinder length="0.5" radius="0.25"/>
      </geometry>
      <origin rpy="1.57079633 0.0 0.0" xyz="0.0 0.0 0.5"/>
      <material name="green"/>
    </visual>
    <collision>
      <geometry>
        <cylinder length="0.5" radius="0.25"/>
      </geometry>
      <origin rpy="1.57079633 0.0 0.0" xyz="0.0 0.0 0.5"/>
    </collision>
    <inertial>
      <origin rpy="1.57079633 0.0 0.0" xyz="0.0 0.0 0.5"/>
      <mass value="0.01"/>
      <inertia ixx="0.0003645833333333333" ixy="0.0" ixz="0.0" iyy="0.0003645833333333333" iyz="0.0" izz="0.0003125"/>
    </inertial>
  </link>
  <link name="rotor_2_link">
    <visual>
      <geometry>
        <cylinder length="0.5" radius="0.25"/>
      </geometry>
      <origin rpy="1.57079633 0.0 0.0" xyz="0.0 0.0 0.5"/>
      <material name="green"/>
    </visual>
    <collision>
      <geometry>
        <cylinder length="0.5" radius="0.25"/>
      </geometry>
      <origin rpy="1.57079633 0.0 0.0" xyz="0.0 0.0 0.5"/>
    </collision>
    <inertial>
      <origin rpy="1.57079633 0.0 0.0" xyz="0.0 0.0 0.5"/>
      <mass value="0.01"/>
      <inertia ixx="0.0003645833333333333" ixy="0.0" ixz="0.0" iyy="0.0003645833333333333" iyz="0.0" izz="0.0003125"/>
    </inertial>
  </link>
  <link name="tool_link">
    <visual>
      <geometry>
        <cylinder length="0.5" radius="0.25"/>
      </geometry>
      <origin xyz="0.0 0.0 0.25"/>
      <material name="white"/>
    </visual>
    <collision>
      <geometry>
        <cylinder length="0.5" radius="0.25"/>
      </geometry>
      <origin xyz="0.0 0.0 0.25"/>
    </collision>
    <inertial>
      <origin xyz="0.0 0.0 0.25"/>
      <mass value="0.01"/>
      <inertia ixx="0.0003645833333333333" ixy="0.0" ixz="0.0" iyy="0.0003645833333333333" iyz="0.0" izz="0.0003125"/>
    </inertial>
  </link>
  <joint name="shoulder_joint" type="revolute">
    <parent link="base_link"/>
    <child link="shoulder_link"/>
    <origin xyz="0.0 0.0 0.0"/>
    <axis xyz="0 0 1"/>
    <limit effort="10.0" lower="-3.141592653589793" upper="3.141592653589793" velocity="5.0"/>
    <dynamics damping="0.7" friction="0.0"/>
    <safety_controller k_position="20" k_velocity="20" soft_lower_limit="-3.1315926535897933" soft_upper_limit="3.1315926535897933"/>
  </joint>
  <joint name="rotor_0_joint" type="revolute">
    <parent link="shoulder_link"/>
    <child link="rotor_0_link"/>
    <origin xyz="0.0 0.0 0.0"/>
    <axis xyz="0 0 1"/>
    <limit effort="10.0" lower="-2.0943951023931953" upper="2.0943951023931953" velocity="5.0"/>
    <dynamics damping="0.7" friction="0.0"/>
    <safety_controller k_position="20" k_velocity="20" soft_lower_limit="-2.0843951023931955" soft_upper_limit="2.0843951023931955"/>
  </joint>
  <joint name="upper_arm_joint" type="revolute">
    <parent link="rotor_0_link"/>
    <child link="upper_arm_link"/>
    <origin xyz="0.0 0.0 0.5"/>
    <axis xyz="0 1 0"/>
    <limit effort="10.0" lower="-3.141592653589793" upper="3.141592653589793" velocity="5.0"/>
    <dynamics damping="0.7" friction="0.0"/>
    <safety_controller k_position="20" k_velocity="20" soft_lower_limit="-3.1315926535897933" soft_upper_limit="3.1315926535897933"/>
  </joint>
  <joint name="rotor_1_joint" type="revolute">
    <parent link="upper_arm_link"/>
    <child link="rotor_1_link"/>
    <origin xyz="0.0 0.0 0.5"/>
    <axis xyz="0 0 1"/>
    <limit effort="10.0" lower="-2.0943951023931953" upper="2.0943951023931953" velocity="5.0"/>
    <dynamics damping="0.7" friction="0.0"/>
    <safety_controller k_position="20" k_velocity="20" soft_lower_limit="-2.0843951023931955" soft_upper_limit="2.0843951023931955"/>
  </joint>
  <joint name="forearm_joint" type="revolute">
    <parent link="rotor_1_link"/>
    <child link="forearm_link"/>
    <origin xyz="0.0 0.0 0.5"/>
    <axis xyz="0 1 0"/>
    <limit effort="10.0" lower="-3.141592653589793" upper="3.141592653589793" velocity="5.0"/>
    <dynamics damping="0.7" friction="0.0"/>
    <safety_controller k_position="20" k_velocity="20" soft_lower_limit="-3.1315926535897933" soft_upper_limit="3.1315926535897933"/>
  </joint>
  <joint name="rotor_2_joint" type="revolute">
    <parent link="forearm_link"/>
    <child link="rotor_2_link"/>
    <origin xyz="0.0 0.0 0.5"/>
    <axis xyz="0 0 1"/>
    <limit effort="10.0" lower="-2.0943951023931953" upper="2.0943951023931953" velocity="5.0"/>
    <dynamics damping="0.7" friction="0.0"/>
    <safety_controller k_position="20" k_velocity="20" soft_lower_limit="-2.0843951023931955" soft_upper_limit="2.0843951023931955"/>
  </joint>
  <joint name="tool_joint" type="revolute">
    <parent link="rotor_2_link"/>
    <child link="tool_link"/>
    <origin xyz="0.0 0.0 0.5"/>
    <axis xyz="0 1 0"/>
    <limit effort="10.0" lower="-3.141592653589793" upper="3.141592653589793" velocity="5.0"/>
    <dynamics damping="0.7" friction="0.0"/>
    <safety_controller k_position="20" k_velocity="20" soft_lower_limit="-3.1315926535897933" soft_upper_limit="3.1315926535897933"/>
  </joint>
  <!-- Transmissions -->
  <arm_simple_transmission name="shoulder" reduction="1.0"/>
  <arm_simple_transmission name="rotor_0" reduction="1.0"/>
  <arm_simple_transmission name="upper_arm" reduction="1.0"/>
  <arm_simple_transmission name="rotor_1" reduction="1.0"/>
  <arm_simple_transmission name="forearm" reduction="1.0"/>
  <arm_simple_transmission name="rotor_2" reduction="1.0"/>
  <arm_simple_transmission name="tool" reduction="1.0"/>
  <!-- Simulation (gazebo) -->
  <arm_gazebo/>
  <link name="finger_1_link">
    <visual>
      <geometry>
        <box size="0.1 0.1 0.5"/>
      </geometry>
      <origin xyz="0.0 0.0 0.25"/>
      <material name="white"/>
    </visual>
    <collision>
      <geometry>
        <box size="0.1 0.1 0.5"/>
      </geometry>
      <origin xyz="0.0 0.0 0.25"/>
    </collision>
    <inertial>
      <origin xyz="0.0 0.0 0.25"/>
      <mass value="0.001"/>
      <inertia ixx="0.00021666666666666666" ixy="0.0" ixz="0.0" iyy="0.00021666666666666666" iyz="0.0" izz="1.6666666666666667e-05"/>
    </inertial>
  </link>
  <link name="finger_2_link">
    <visual>
      <geometry>
        <box size="0.1 0.1 0.5"/>
      </geometry>
      <origin xyz="0.0 0.0 0.25"/>
      <material name="white"/>
    </visual>
    <collision>
      <geometry>
        <box size="0.1 0.1 0.5"/>
      </geometry>
      <origin xyz="0.0 0.0 0.25"/>
    </collision>
    <inertial>
      <origin xyz="0.0 0.0 0.25"/>
      <mass value="0.001"/>
      <inertia ixx="0.00021666666666666666" ixy="0.0" ixz="0.0" iyy="0.00021666666666666666" iyz="0.0" izz="1.6666666666666667e-05"/>
    </inertial>
  </link>
  <joint name="finger_1_joint" type="prismatic">
    <parent link="tool_link"/>
    <child link="finger_1_link"/>
    <origin xyz="0.0 0.2 0.5"/>
    <axis xyz="0 1 0"/>
    <limit effort="1.0" lower="-0.15" upper="0.0" velocity="5.0"/>
    <dynamics damping="0.5" friction="0.0"/>
    <safety_controller k_position="20" k_velocity="20" soft_lower_limit="-0.13" soft_upper_limit="-0.02"/>
  </joint>
  <joint name="finger_2_joint" type="prismatic">
    <parent link="tool_link"/>
    <child link="finger_2_link"/>
    <origin xyz="0.0 -0.2 0.5"/>
    <axis xyz="0 1 0"/>
    <limit effort="1.0" lower="0" upper="0.15" velocity="5.0"/>
    <dynamics damping="0.5" friction="0.0"/>
    <safety_controller k_position="20" k_velocity="20" soft_lower_limit="0.02" soft_upper_limit="0.13"/>
  </joint>
  <!-- Grasping frame -->
  <link name="grasping_frame">
    <inertial>
      <origin rpy="0 0 0" xyz="0 0 0"/>
      <mass value="0.0001"/>
      <inertia ixx="1.6666666666666667e-11" ixy="0.0" ixz="0.0" iyy="1.6666666666666667e-11" iyz="0.0" izz="1.6666666666666667e-11"/>
    </inertial>
  </link>
  <joint name="grasping_frame_joint" type="fixed">
    <parent link="tool_link"/>
    <child link="grasping_frame"/>
    <origin rpy="0 0 0" xyz="0 0 0.75"/>
  </joint>
  <!-- Transmissions -->
  <arm_simple_transmission name="finger_1" reduction="1.0"/>
  <arm_simple_transmission name="finger_2" reduction="1.0"/>
  <!-- Simulation (gazebo) -->
  <gripper_gazebo/>
</robot>
